Workbook
Name Slicer_Representative: #N/A
Name Slicer_Representative1: #N/A
Name Slicer_Representative2: #N/A

Sheet Data1
A1: Emp ID | B1: Name | C1: Gender | D1: Department | E1: Salary | F1: Start Date | G1: FTE | H1: Employee type | I1: Work location
A2: PR00007 | B2: Torrance Collier | C2: Female | D2: Training | E2: $96,135.75 | F2: 7/13/2020 | G2: 0.3 | H2: Permanent | I2: Wellington, New Zealand
A3: PR00095 | B3: Devrat Damarsingh | C3: Female | D3: Business Development | E3: $70,649.46 | F3: 1/13/2020 | G3: 1 | H3: Permanent | I3: Hyderabad, India
A4: PR00113 | B4: Van Tuxwell | C4: Female | D4: Business Development | E4: $80,695.74 | F4: 9/17/2018 | G4: 1 | H4: Permanent | I4: Columbus, USA
A5: PR00113 | B5: Van Tuxwell | C5: Female | D5: Business Development | E5: $80,695.74 | F5: 9/17/2018 | G5: 1 | H5: Permanent | I5: Columbus, USA
A6: PR00147 | B6: Minerva Ricardot | C6: Male | D6: ??? | E6: $120,000.00 | F6: 43445 | G6: 1 | H6: Permanent | I6: Remote
A7: PR00246 | B7: Husein Augar | C7: Female | D7: Marketing | E7: $67,905.80 | F7: 12/29/2020 | G7: 1 | H7: Permanent | I7: Remote
A8: PR00419 | B8: Billi Fellgate | C8: Female | D8: Business Development | E8: $68,980.52 | F8: 1/29/2019 | G8: 0.8 | H8: Permanent | I8: Remote
A9: PR00576 | B9: Lalitchandra Vadali | C9: Female | D9: Legal | E9: $63,705.40 | F9: 43593 | G9: 1 | H9: Permanent | I9: Hyderabad, India
A10: PR00746 | B10: Hogan Iles | C10: Female | D10: Accounting | E10: $114,177.23 | F10: 3/18/2020 | G10: 1 | H10: Permanent | I10: Wellington, New Zealand
A11: PR00770 | B11: Beryl Burnsyde | C11: Male | D11: Legal | E11: $29,774.76 | F11: 43840 | G11: 1 | H11: Permanent | I11: Wellington, New Zealand
A12: PR00882 | B12: Jill Shipsey | C12: Male | D12: Accounting | E12: $52,963.65 | F12: 44231 | G12: 0.3 | H12: Permanent | I12: Columbus, USA
A13: PR00893 | B13: Vasavi Veeravasarapu | C13: Male | D13: Human Resources | E13: $50,310.09 | F13: 3/30/2021 | G13: 0.4 | H13: Permanent | I13: Hyderabad, India
A14: PR00916 | B14: Inger Chapelhow | C14: Female | D14: Research and Development | E14: $84,309.95 | F14: 44207 | G14: 1 | H14: Permanent | I14: Remote
A15: PR01055 | B15: Devasree Fullara Saurin | C15: Male | D15: Accounting | E15: $35,936.31 | F15: 5/21/2018 | G15: 1 | H15: Permanent | I15: Chennai, India
A16: PR01159 | B16: Mollie Hanway | C16: Male | D16: ??? | E16: $112,645.99 | F16: 10/21/2019 | G16: 0.6 | H16: Permanent | I16: Seattle, USA
A17: PR01211 | B17: Enoch Dowrey | C17: Male | D17: Accounting | E17: $91,645.04 | F17: 1/27/2021 | G17: 1 | H17: Permanent | I17: Auckland, New Zealand
A18: PR01269 | B18: Eleonore Airdrie | C18: Female | D18: Engineering | E18: $97,105.19 | F18: 8/17/2021 | G18: 1 | H18: Permanent | I18: Columbus, USA
A19: PR01306 | B19: Patti Dradey | C19: Male | D19: Services | E19: $84,742.86 | F19: 9/24/2020 | G19: 1 | H19: Permanent | I19: Auckland, New Zealand
A20: PR01346 | B20: Adolph McNalley | C20: Male | D20: Business Development | E20: $85,918.61 | F20: 43222 | G20: 1 | H20: Permanent | I20: Columbus, USA
A21: PR01383 | B21: Addi Studdeard | C21: Female | D21: Product Management | E21: $72,502.61 | F21: 44410 | G21: 1 | H21: Permanent | I21: Wellington, New Zealand
A22: PR01476 | B22: Jaishree Atasi Yavatkar | C22: Male | D22: Services | E22: $77,096.05 | F22: 4/27/2018 | G22: 1 | H22: Permanent | I22: Chennai, India
A23: PR01662 | B23: Genevra Friday | C23: Female | D23: Research and Development | E23: $50,449.46 | F23: 11/14/2018 | G23: 0.8 | H23: Permanent | I23: Auckland, New Zealand
A24: PR01943 | B24: Rameshwari Chikodi | C24: Male | D24: Human Resources | E24: $48,525.71 | F24: 6/13/2018 | G24: 1 | H24: Permanent | I24: Hyderabad, India
A25: PR01956 | B25: Jamesy O'Ferris | C25: Male | D25: Accounting | E25: $36,547.58 | F25: 43445 | G25: 1 | H25: Permanent | I25: Remote
A26: PR01956 | B26: Jamesy O'Ferris | C26: Male | D26: Accounting | E26: $36,547.58 | F26: 43445 | G26: 1 | H26: Permanent | I26: Remote
A27: PR02010 | B27: Prerana Nishita | C27: Male | D27: Product Management | E27: $115,191.38 | F27: 6/22/2020 | G27: 1 | H27: Permanent | I27: Hyderabad, India
A28: PR02016 | B28: Iris Wagg | C28: Female | D28: ??? | E28: $58,861.19 | F28: 43684 | G28: 1 | H28: Permanent | I28: Columbus, USA
A29: PR02113 | B29: Beverie Moffet | C29: Female | D29: Support | E29: $75,974.99 | F29: 44024 | G29: 1 | H29: Permanent | I29: Remote
A30: PR02140 | B30: Anjushri Chandiramani | C30: Male | D30: Accounting | E30: $95,954.02 | F30: 43803 | G30: 0.3 | H30: Permanent | I30: Hyderabad, India
A31: PR02208 | B31: Gowri Sankar Chakrala | C31: Female | D31: Training | E31: $102,934.09 | F31: 4/29/2021 | G31: 1 | H31: Permanent | I31: Hyderabad, India
A32: PR02275 | B32: Louise Lamming | C32: Female | D32: Sales | E32: $41,934.71 | F32: 43780 | G32: 1 | H32: Permanent | I32: Remote
A33: PR02288 | B33: Althea Bronger | C33: Male | D33: Product Management | E33: $104,335.04 | F33: 2/13/2020 | G33: 1 | H33: Permanent | I33: Columbus, USA
A34: PR02321 | B34: Evanne Sheryn | C34: Female | D34: Services | E34: $81,897.79 | F34: 2/15/2018 | G34: 1 | H34: Permanent | I34: Auckland, New Zealand
A35: PR02436 | B35: Marmaduke Worssam | C35: Female | D35: Engineering | E35: $78,378.20 | F35: 12/31/2018 | G35: 0.4 | H35: Permanent | I35: Remote
A36: PR02603 | B36: Dinanath Simhambhatla | C36: Female | D36: Human Resources | E36: $61,994.76 | F36: 11/25/2019 | G36: 0.3 | H36: Permanent | I36: Hyderabad, India
A37: PR02782 | B37: Isaak Rawne | C37: Male | D37: Marketing | E37: $37,362.30 | F37: 6/26/2019 | G37: 1 | H37: Permanent | I37: Auckland, New Zealand
A38: PR02957 | B38: Vaughn Carvill | C38: Female | D38: Training | E38: $84,745.93 | F38: 8/30/2019 | G38: 1 | H38: Permanent | I38: Wellington, New Zealand
A39: PR03034 | B39: Sreenivasa Naik Gudiwada | C39: Male | D39: Sales | E39: $32,192.15 | F39: 44296 | G39: 1 | H39: Permanent | I39: Hyderabad, India
A40: PR03137 | B40: Jagajeet Viraj | C40: Male | D40: Support | E40: $36,714.38 | F40: 44116 | G40: 1 | H40: Permanent | I40: Chennai, India
...

Sheet Medals
A1: Rank | B1: Country | C1: Gold | D1: Silver | E1: Bronze | F1: Total | G1: Division
A2: 1 | B2: United States | C2: 39 | D2: 41 | E2: 33 | F2: 113 | G2: 0.34513274
A3: 2 | B3: China | C3: 38 | D3: 32 | E3: 19 | F3: 89 | G3: 0.42696629
A4: 3 | B4: Japan | C4: 27 | D4: 14 | E4: 17 | F4: 58 | G4: 0.46551724
A5: 4 | B5: Great Britain | C5: 22 | D5: 20 | E5: 22 | F5: 64 | G5: 0.34375
A6: 5 | B6: ROC | C6: 20 | D6: 28 | E6: 23 | F6: 71 | G6: 0.28169014
A7: 6 | B7: Australia | C7: 17 | D7: 7 | E7: 22 | F7: 46 | G7: 0.36956522
A8: 7 | B8: Netherlands | C8: 10 | D8: 12 | E8: 14 | F8: 36 | G8: 0.27777778
A9: 8 | B9: France | C9: 10 | D9: 12 | E9: 11 | F9: 33 | G9: 0.3030303
A10: 9 | B10: Germany | C10: 10 | D10: 11 | E10: 16 | F10: 37 | G10: 0.27027027
A11: 10 | B11: Italy | C11: 10 | D11: 10 | E11: 20 | F11: 40 | G11: 0.25
A12: 11 | B12: Canada | C12: 7 | D12: 7 | E12: 10 | F12: 24 | G12: 0.29166667
A13: 12 | B13: Brazil | C13: 7 | D13: 6 | E13: 8 | F13: 21 | G13: 0.33333333
... A94: 86 | B94: Syria | C94: 0 | D94: 0 | E94: 1 | F94: 1 | G94: 0

Sheet Staff
A1: Emp ID | B1: First Name | C1: Last Name | D1: Gender | E1: Department | F1: Salary | G1: Salary Bucket | H1: Start Date | I1: FTE | J1: Employee type | K1: Work location | L1: Age | M1: Work Type
A2: PR00147 | B2: Minerva | C2: Ricardot | D2: Male | E2: Engineering | F2: 120000 | G2: Above 100k | H2: 43416 | I2: 1 | J2: Permanent | K2: Remote | L2: 6.6767123 | M2: full time
A3: PR04686 | B3: Oona | C3: Donan | D3: Female | E3: Business Development | F3: 98000 | G3: 50k to 100k | H3: 43710 | I3: 0.9 | J3: Permanent | K3: Seattle, USA | L3: 5.8712329 | M3: Part time
A4: SQ04612 | B4: Mick | C4: Spraberry | D4: Female | E4: Services | F4: 120000 | G4: Above 100k | H4: 43902 | I4: 0.9 | J4: Permanent | K4: Remote | L4: 5.3452055 | M4: Part time
A5: VT01803 | B5: Freddy | C5: Linford | D5: Female | E5: Training | F5: 93128.34 | G5: 50k to 100k | H5: 43164 | I5: 1 | J5: Fixed Term | K5: Seattle, USA | L5: 7.3671233 | M5: full time
A6: TN02749 | B6: Parasuramudu | C6: Jamakayala | D6: Female | E6: Training | F6: 57002.02 | G6: 50k to 100k | H6: 43192 | I6: 0.7 | J6: Permanent | K6: Hyderabad, India | L6: 7.290411 | M6: Part time
A7: SQ00144 | B7: Collen | C7: Dunbleton | D7: Male | E7: Engineering | F7: 118976.16 | G7: Above 100k | H7: 44120 | I7: 1 | J7: Permanent | K7: Wellington, New Zealand | L7: 4.7479452 | M7: full time
A8: PR04601 | B8: Yedukondalu | C8: Panditula | D8: Missing | E8: Support | F8: 104802.63 | G8: Above 100k | H8: 44502 | I8: 1 | J8: Permanent | K8: Hyderabad, India | L8: 3.7013699 | M8: full time
A9: SQ01854 | B9: Jessica | C9: Callcott | D9: Female | E9: Marketing | F9: 66017.18 | G9: 50k to 100k | H9: 43643 | I9: 0.9 | J9: Permanent | K9: Remote | L9: 6.0547945 | M9: Part time
A10: SQ00612 | B10: Leena | C10: Bruckshaw | D10: Male | E10: Research and Development | F10: 74279.01 | G10: 50k to 100k | H10: 43466 | I10: 1 | J10: Permanent | K10: Wellington, New Zealand | L10: 6.539726 | M10: full time
A11: PR00419 | B11: Billi | C11: Fellgate | D11: Female | E11: Business Development | F11: 68980.52 | G11: 50k to 100k | H11: 43494 | I11: 0.8 | J11: Permanent | K11: Remote | L11: 6.4630137 | M11: Part time
A12: VT00578 | B12: Magnum | C12: Locksley | D12: Female | E12: Services | F12: 42314.39 | G12: Under 50k | H12: 44487 | I12: 1 | J12: Fixed Term | K12: Remote | L12: 3.7424658 | M12: full time
A13: TN01281 | B13: Cletus | C13: McGarahan | D13: Female | E13: Engineering | F13: 114425.19 | G13: Above 100k | H13: 43857 | I13: 1 | J13: Permanent | K13: Wellington, New Zealand | L13: 5.4684932 | M13: full time
... A261: SQ03625 | B261: Fidela | C261: Artis | D261: Female | E261: Sales | F261: 78020.39 | G261: 50k to 100k | H261: 43899 | I261: 1 | J261: Permanent | K261: Remote | L261: 5.3534247 | M261: full time

Sheet P Query
C1: How to use Power Query
C4: Source 1 | D4: https://en.wikipedia.org/wiki/2020_Summer_Olympics_medal_table
C5: Source 2 | D5: Staff data file

Sheet 1
B2: Department | C2: Headcount | D2: Total Salary | E2: Avg. Salary
B3: Engineering | C3: =COUNTIFS(Staff[Department],B3) -> 26 | D3: {=SUMIFS(Staff[Salary],Staff[Department],B3:B14)} -> 2131387.5 | E3: {=AVERAGEIFS(Staff[Salary],Staff[Department],B3:B14)} -> 81976.442 | AE3: Lowest, Highest and top 5 salary values
B4: Business Development | C4: =COUNTIFS(Staff[Department],B4) -> 26 | D4: 2074327 | E4: 79781.806
B5: Services | C5: =COUNTIFS(Staff[Department],B5) -> 21 | D5: 1568153.5 | E5: 74673.975 | AE5: all emps | AF5: Male | AG5: Female
B6: Training | C6: =COUNTIFS(Staff[Department],B6) -> 24 | D6: 2013215.2 | E6: 83883.965 | AD6: Lowest salary | AE6: =MIN(Staff[Salary]) -> 28160.79 | AF6: =_xlfn.MINIFS(Staff[Salary],Staff[Gender],$AF$5) -> 28160.79 | AG6: =_xlfn.MINIFS(Staff[Salary],Staff[Gender],$AG$5) -> 28305.08
B7: Support | C7: =COUNTIFS(Staff[Department],B7) -> 17 | D7: 1129351.7 | E7: 66432.456 | AD7: Highest Salary | AE7: =MAX(Staff[Salary]) -> 120000 | AF7: =_xlfn.MAXIFS(Staff[Salary],Staff[Gender],AF5) -> 120000 | AG7: =_xlfn.MAXIFS(Staff[Salary],Staff[Gender],AF5) -> 120000
B8: Marketing | C8: =COUNTIFS(Staff[Department],B8) -> 12 | D8: 773295.6 | E8: 64441.3 | AD8: Top 5 salaries | AE8: =LARGE(Staff[Salary],AI8) -> 120000 | AI8: 1
B9: Research and Development | C9: =COUNTIFS(Staff[Department],B9) -> 18 | D9: 1204393.8 | E9: 66910.766 | AE9: =LARGE(Staff[Salary],2) -> 120000 | AI9: 2
B10: Human Resources | C10: =COUNTIFS(Staff[Department],B10) -> 22 | D10: 1608406.3 | E10: 73109.378 | AE10: 119022 | AI10: 3
B11: Accounting | C11: =COUNTIFS(Staff[Department],B11) -> 26 | D11: 1814980.6 | E11: 69806.946 | AE11: 118976 | AI11: 4
B12: Sales | C12: =COUNTIFS(Staff[Department],B12) -> 18 | D12: 1294147.7 | E12: 71897.096 | U12: all such female employees | X12: 3 | AE12: 118442 | AI12: 5
B13: Product Management | C13: =COUNTIFS(Staff[Department],B13) -> 29 | D13: 2180192.9 | E13: 75179.064 | O13: all employee with >100k salary | S13: 108000 | U13: columns 1,2,3,5,6
B14: Legal | C14: =COUNTIFS(Staff[Department],B14) -> 21 | D14: 1412092.9 | E14: 67242.518 | O14: columns1,2,3,5,6
P15: {=_xlfn.CHOOSECOLS(Staff[#Headers],1,2,3,5,6)} -> Emp ID | Q15: First Name | R15: Last Name | S15: Department | T15: Salary | V15: {=_xlfn._xlws.FILTER(Staff[[Emp ID]:[Salary]],(Staff[Salary]>S13)*(Staff[Gender]="female"))} -> SQ04612 | W15: Mick | X15: Spraberry | Y15: Female | Z15: Services | AA15: 120000
B16: {=Staff[#Headers]} -> Emp ID | C16: First Name | D16: Last Name | E16: Gender | F16: Department | G16: Salary | H16: Salary Bucket | I16: Start Date | J16: FTE | K16: Employee type | L16: Work location | M16: Age | N16: Work Type | P16: {=_xlfn.CHOOSECOLS(_xlfn._xlws.FILTER(Staff[],Staff[Salary]>S13),1,2,3,5,6)} -> PR00147 | Q16: Minerva | R16: Ricardot | S16: Engineering | T16: 120000 | V16: TN01281 | W16: Cletus | X16: McGarahan | Y16: Female | Z16: Engineering | AA16: 114425.19
B17: {=_xlfn._xlws.FILTER(Staff[Salary], Staff[Salary] > 100000)} -> 120000 | C17: {=_xlfn._xlws.FILTER(Staff[First Name], Staff[Salary] > 100000)} -> Minerva | D17: {=_xlfn._xlws.FILTER(Staff[Last Name], Staff[Salary] > 100000)} -> Ricardot | E17: {=_xlfn._xlws.FILTER(Staff[Gender], Staff[Salary] > 100000)} -> Male | F17: {=_xlfn._xlws.FILTER(Staff[Department], Staff[Salary] > 100000)} -> Engineering | G17: {=_xlfn._xlws.FILTER(Staff[Salary], Staff[Salary] > 100000)} -> 120000 | H17: {=_xlfn._xlws.FILTER(Staff[Salary Bucket], Staff[Salary] > 100000)} -> Above 100k | I17: {=_xlfn._xlws.FILTER(Staff[Start Date], Staff[Salary] > 100000)} -> 43416 | J17: {=_xlfn._xlws.FILTER(Staff[FTE], Staff[Salary] > 100000)} -> 1 | K17: {=_xlfn._xlws.FILTER(Staff[Employee type], Staff[Salary] > 100000)} -> Permanent | L17: {=_xlfn._xlws.FILTER(Staff[Work location], Staff[Salary] > 100000)} -> Remote | M17: {=_xlfn._xlws.FILTER(Staff[Age], Staff[Salary] > 100000)} -> 6.6767123 | N17: {=_xlfn._xlws.FILTER(Staff[Work Type], Staff[Salary] > 100000)} -> full time | P17: SQ04612 | Q17: Mick | R17: Spraberry | S17: Services | T17: 120000 | V17: VT04681 | W17: Nickolai | X17: Artin | Y17: Female | Z17: Product Management | AA17: 110906.35
B18: 120000 | C18: Mick | D18: Spraberry | E18: Female | F18: Services | G18: 120000 | H18: Above 100k | I18: 43902 | J18: 0.9 | K18: Permanent | L18: Remote | M18: 5.3452055 | N18: Part time | P18: SQ00144 | Q18: Collen | R18: Dunbleton | S18: Engineering | T18: 118976.16 | V18: VT04093 | W18: Prasanna | X18: Lakshmi | Y18: Female | Z18: Training | AA18: 116767.63
B19: 118976.16 | C19: Collen | D19: Dunbleton | E19: Male | F19: Engineering | G19: 118976.16 | H19: Above 100k | I19: 44120 | J19: 1 | K19: Permanent | L19: Wellington, New Zealand | M19: 4.7479452 | N19: full time | P19: TN01281 | Q19: Cletus | R19: McGarahan | S19: Engineering | T19: 114425.19 | V19: SQ00498 | W19: Amery | X19: Ofer | Y19: Female | Z19: Legal | AA19: 111049.84 | AD19: Top 5 salaries | AE19: {=_xlfn.TAKE(_xlfn._xlws.SORT(Staff[Salary],,-1),5)} -> 120000
B20: 104802.63 | C20: Yedukondalu | D20: Panditula | E20: Missing | F20: Support | G20: 104802.63 | H20: Above 100k | I20: 44502 | J20: 1 | K20: Permanent | L20: Hyderabad, India | M20: 3.7013699 | N20: full time | P20: SQ01620 | Q20: Westbrook | R20: Brandino | S20: Legal | T20: 113616.23 | V20: PR00746 | W20: Hogan | X20: Iles | Y20: Female | Z20: Accounting | AA20: 114177.23 | AD20: w SORT + Take | AE20: 120000
B21: 114425.19 | C21: Cletus | D21: McGarahan | E21: Female | F21: Engineering | G21: 114425.19 | H21: Above 100k | I21: 43857 | J21: 1 | K21: Permanent | L21: Wellington, New Zealand | M21: 5.4684932 | N21: full time | P21: VT04681 | Q21: Nickolai | R21: Artin | S21: Product Management | T21: 110906.35 | V21: TN00579 | W21: Rafaelita | X21: Blaksland | Y21: Female | Z21: Services | AA21: 109163.39 | AE21: 119022.49
B22: 104335.04 | C22: Althea | D22: Bronger | E22: Male | F22: Product Management | G22: 104335.04 | H22: Above 100k | I22: 43874 | J22: 1 | K22: Permanent | L22: Columbus, USA | M22: 5.4219178 | N22: full time | P22: VT02801 | Q22: Shellysheldon | R22: Mahady | S22: Training | T22: 114691.03 | V22: SQ02174 | W22: Sidoney | X22: Yitzhok | Y22: Female | Z22: Engineering | AA22: 118442.54 | AE22: 118976.16
B23: 113616.23 | C23: Westbrook | D23: Brandino | E23: Male | F23: Legal | G23: 113616.23 | H23: Above 100k | I23: 43255 | J23: 1 | K23: Permanent | L23: Remote | M23: 7.1178082 | N23: full time | P23: VT04093 | Q23: Prasanna | R23: Lakshmi | S23: Training | T23: 116767.63 | V23: VT04093 | W23: Baruna | X23: Ogale | Y23: Female | Z23: Training | AA23: 116767.63 | AE23: 118442.54
B24: 110906.35 | C24: Nickolai | D24: Artin | E24: Female | F24: Product Management | G24: 110906.35 | H24: Above 100k | I24: 43434 | J24: 1 | K24: Temporary | L24: Wellington, New Zealand | M24: 6.6273973 | N24: full time | P24: VT03421 | Q24: Alic | R24: Bagg | S24: Legal | T24: 113747.56 | V24: SQ02624 | W24: Gwenneth | X24: Fealey | Y24: Female | Z24: Engineering | AA24: 114772.32
B25: 100371.31 | C25: Shaylyn | D25: Ransbury | E25: Female | F25: Support | G25: 100371.31 | H25: Above 100k | I25: 44067 | J25: 0.8 | K25: Fixed Term | L25: Auckland, New Zealand | M25: 4.8931507 | N25: Part time | P25: VT02491 | Q25: Alexis | R25: Gotfrey | S25: Engineering | T25: 114465.93
B26: 114691.03 | C26: Shellysheldon | D26: Mahady | E26: Male | F26: Training | G26: 114691.03 | H26: Above 100k | I26: 44039 | J26: 1 | K26: Temporary | L26: Wellington, New Zealand | M26: 4.969863 | N26: full time | P26: PR01159 | Q26: Mollie | R26: Hanway | S26: Engineering | T26: 112645.99
B27: 102934.09 | C27: Gowri | D27: Sankar | E27: Female | F27: Training | G27: 102934.09 | H27: Above 100k | I27: 44315 | J27: 1 | K27: Permanent | L27: Hyderabad, India | M27: 4.2136986 | N27: full time | P27: VT01893 | Q27: Lindy | R27: Guillet | S27: Training | T27: 112778.28
B28: 116767.63 | C28: Prasanna | D28: Lakshmi | E28: Female | F28: Training | G28: 116767.63 | H28: Above 100k | I28: 43949 | J28: 0.4 | K28: Temporary | L28: Chennai, India | M28: 5.2164384 | N28: Part time | P28: PR02010 | Q28: Prerana | R28: Nishita | S28: Product Management | T28: 115191.38
B29: 113747.56 | C29: Alic | D29: Bagg | E29: Male | F29: Legal | G29: 113747.56 | H29: Above 100k | I29: 44270 | J29: 0.7 | K29: Temporary | L29: Columbus, USA | M29: 4.3369863 | N29: Part time | P29: SQ00498 | Q29: Amery | R29: Ofer | S29: Legal | T29: 111049.84
B30: 114465.93 | C30: Alexis | D30: Gotfrey | E30: Male | F30: Engineering | G30: 114465.93 | H30: Above 100k | I30: 43291 | J30: 1 | K30: Temporary | L30: Wellington, New Zealand | M30: 7.0191781 | N30: full time | P30: SQ04603 | Q30: Natalee | R30: Craiker | S30: Product Management | T30: 111229.47
B31: 106775.14 | C31: Subbarao | D31: Malladi | E31: Male | F31: Product Management | G31: 106775.14 | H31: Above 100k | I31: 43563 | J31: 1 | K31: Fixed Term | L31: Hyderabad, India | M31: 6.2739726 | N31: full time | P31: VT04028 | Q31: Michale | R31: Rolf | S31: Services | T31: 111815.49
B32: 112645.99 | C32: Mollie | D32: Hanway | E32: Male | F32: Engineering | G32: 112645.99 | H32: Above 100k | I32: 43759 | J32: 0.6 | K32: Permanent | L32: Seattle, USA | M32: 5.7369863 | N32: Part time | P32: VT04028 | Q32: Michale | R32: Rolf | S32: Services | T32: 111815.49
B33: 107107.6 | C33: Ramalingam | D33: Kothapeta | E33: Missing | F33: Accounting | G33: 107107.6 | H33: Above 100k | I33: 43325 | J33: 0.9 | K33: Permanent | L33: Chennai, India | M33: 6.9260274 | N33: Part time | P33: SQ00022 | Q33: Carlin | R33: Demke | S33: Business Development | T33: 110042.37
B34: 101187.36 | C34: Audry | D34: Yu | E34: Female | F34: Training | G34: 101187.36 | H34: Above 100k | I34: 43258 | J34: 1 | K34: Fixed Term | L34: Columbus, USA | M34: 7.109589 | N34: full time | P34: SQ03116 | Q34: Syd | R34: Fearn | S34: Engineering | T34: 108872.77
B35: 104038.9 | C35: Tristam | D35: Cuming | E35: Female | F35: Support | G35: 104038.9 | H35: Above 100k | I35: 43815 | J35: 1 | K35: Fixed Term | L35: Remote | M35: 5.5835616 | N35: full time | P35: VT01893 | Q35: Lindy | R35: Guillet | S35: Training | T35: 112778.28
B36: 112778.28 | C36: Lindy | D36: Guillet | E36: Male | F36: Training | G36: 112778.28 | H36: Above 100k | I36: 43250 | J36: 1 | K36: Fixed Term | L36: Remote | M36: 7.1315068 | N36: full time | P36: PR03886 | Q36: Edd | R36: MacKnockiter | S36: Accounting | T36: 119022.49
... B43: 110042.37 | C43: Carlin | D43: Demke | E43: Male | F43: Business Development | G43: 110042.37 | H43: Above 100k | I43: 43914 | J43: 1 | K43: Permanent | L43: Columbus, USA | M43: 5.3123288 | N43: full time | P43: VT03421 | Q43: Alic | R43: Bagg | S43: Legal | T43: 113747.56
B44: 108872.77 | C44: Syd | D44: Fearn | E44: Male | F44: Engineering | G44: 108872.77 | H44: Above 100k | I44: 43521 | J44: 1 | K44: Permanent | L44: Remote | M44: 6.3890411 | N44: full time
B45: 106665.67 | C45: Theresita | D45: Chasmer | E45: Female | F45: Product Management | G45: 106665.67 | H45: Above 100k | I45: 43311 | J45: 1 | K45: Temporary | L45: Columbus, USA | M45: 6.9643836 | N45: full time
B46: 100424.23 | C46: Collin | D46: Jagson | E46: Male | F46: Services | G46: 100424.23 | H46: Above 100k | I46: 43801 | J46: 1 | K46: Permanent | L46: Auckland, New Zealand | M46: 5.6219178 | N46: full time
B47: 112778.28 | C47: Lindy | D47: Guillet | E47: Male | F47: Training | G47: 112778.28 | H47: Above 100k | I47: 43250 | J47: 1 | K47: Fixed Term | L47: Remote | M47: 7.1315068 | N47: full time
...

Sheet  Departments
A1: List all departments and count them
B3: Department: | E3: count: | F3: =COUNTA(_xlfn.ANCHORARRAY(B5)) -> 12
B5: {=_xlfn._xlws.SORT(_xlfn.UNIQUE(Staff[Department]))} -> Accounting
B6: Business Development
B7: Engineering
B8: Human Resources
B9: Legal
B10: Marketing
B11: Product Management
B12: Research and Development
B13: Sales
B14: Services
B15: Support
B16: Training

Sheet concepts
C1: Essential Excel Functions & Formulas
D5: Business Question: | F5: Function(s) you'll learn: | G5: Challenge for you…
C6: 1 | D6: Total Salary and headcount by department | F6: SUMIFS, COUNTIFS | G6: Permanent headcount
C7: 2 | D7: All employees with more than $100k salary | F7: FILTER
C8: 3 | D8: All female employees with more than $100k salary | F8: FILTER, * | G8: who joined in 2020 or after…
C9: 4 | D9: Lowest, highest and top 5 salary values | F9: MIN, MAX, LARGE, SORT + TAKE
C10: 5 | D10: List of all departments | F10: UNIQUE, COUNTA, # | G10: All depts in one cell, comma seperated
C11: 6 | D11: Employee details lookup | F11: VLOOKUP, INDEX + MATCH
C12: 7 | D12: Employee details lookup | F12: XLOOKUP, IFERROR | G12: Find all employees with 120,000 salary
C13: 8 | D13: Complex formula: Highest salary person | F13: XLOOKUP + MAX
C14: 9 | D14: Complex formula: All employees joined in March | F14: FILTER + MONTH | G14: Female employees with Monday start
C15: 10 | D15: Complex formula: Department report of headcounts, salaries and % diff from overall average | F15: UNIQUE, SUMIFS, COUNTIFS, #, CONDITIONAL FORMATTING | G15: Calculate Median Salary and Female Ratio

Sheet vlookup
B2: Employee Lookup | C2: =vlookup(c4,staff,2,False) | F2: With Xlookup
B4: Employee ID | C4: PR03886 | F4: =_xlfn.XLOOKUP(C4,Staff[Emp ID],Staff[First Name],"Not Found") -> Edd
F5: =_xlfn.XLOOKUP(C4,Staff[Emp ID],Staff[Last Name]) -> MacKnockiter
B6: First Name: | C6: =VLOOKUP(C4,Staff[],2,FALSE) -> Edd | F6: =_xlfn.XLOOKUP(C4,Staff[Emp ID],Staff[Department]) -> Accounting
B7: Last name: | C7: =VLOOKUP(C4,Staff[],3,FALSE) -> MacKnockiter | F7: =_xlfn.XLOOKUP(C4,Staff[Emp ID],Staff[Salary]) -> 119022.49
B8: Department | C8: =VLOOKUP(C4,Staff[],5,FALSE) -> Accounting | F8: =_xlfn.XLOOKUP(C4,Staff[Emp ID],Staff[Gender]) -> Male
B9: Salary: | C9: =VLOOKUP(C4,Staff[],6,FALSE) -> 119022.49
H10: Entire Data Using Xlookup
H12: {=TRANSPOSE(_xlfn.XLOOKUP(C15,Staff[Last Name],Staff[]))} -> TN03331
H13: Crawford
H14: Scad
B15: Last Name: | C15: Scad | H15: Male
C16: "=MATCH(C16,Staff[Last Name],0)" | H16: Human Resources
C17: =MATCH(C15,Staff[Last Name],0) -> 61 | H17: 72876.91
H18: 50k to 100k
B19: Employee ID | C19: =INDEX(Staff[Emp ID],MATCH(C15,Staff[Last Name],0)) -> TN03331 | F19: =_xlfn.XLOOKUP(C15,Staff[Last Name],Staff[Emp ID],"Not Found") -> TN03331 | H19: 43612
B20: Department | C20: =INDEX(Staff[Department],MATCH(C15,Staff[Last Name],0)) -> Human Resources | F20: =_xlfn.XLOOKUP(C15,Staff[Last Name],Staff[Department],"Not Found") -> Human Resources | H20: 0.4
B21: Salary | C21: =INDEX(Staff[Salary],MATCH(C15,Staff[Last Name],0)) -> 72876.91 | F21: =_xlfn.XLOOKUP(C15,Staff[Last Name],Staff[Salary],"Not Found") -> 72876.91 | H21: Fixed Term
H22: Auckland, New Zealand
H23: 6.139726
H24: Part time
B28: Complex formula : highest salary person | G28: Complex Formula: all employees who joined in march
B30: One person: | C30: {=_xlfn.XLOOKUP(MAX(Staff[Salary]),Staff[Salary],Staff[First Name]&" "&Staff[Last Name])} -> Minerva Ricardot | G30: Emp ID | H30: First name | I30: Last Name
G31: {=_xlfn._xlws.FILTER(Staff[[Emp ID]:[Last Name]], MONTH(Staff[Start Date])=3)} -> SQ04612 | H31: Mick | I31: Spraberry
B32: All persons: | C32: {=_xlfn.TEXTJOIN(",",,_xlfn._xlws.FILTER(Staff[First Name]&" "&Staff[Last Name],Staff[Salary]=MAX(Staff[Salary])))} -> Minerva Ricardot,Mick Spraberry | G32: VT01803 | H32: Freddy | I32: Linford
G33: VT02417 | H33: Evangelina | I33: Lergan
G34: PR00893 | H34: Vasavi | I34: Veeravasarapu
G35: VT03421 | H35: Alic | I35: Bagg
G36: VT03993 | H36: Dulce | I36: Colbeck
G37: SQ01519 | H37: Caron | I37: Kolakovic
G38: VT04028 | H38: Michale | I38: Rolf
G39: VT04028 | H39: Michale | I39: Rolf
G40: SQ00022 | H40: Carlin | I40: Demke
G41: TN01256 | H41: Shattesh | I41: Utpat
G42: PR00746 | H42: Hogan | I42: Iles
G43: SQ00105 | H43: Sarayu | I43: Ragunathan
G44: VT04415 | H44: Malory | I44: Biles
... G52: SQ03625 | H52: Fidela | I52: Artis

Sheet Dept Report
B1: Comples Formula: department report of headcounts, salaries and % diff from overall average
B3: All Departments | C3: =COUNTA(Staff[Emp ID]) -> 260 | D3: =AVERAGE(Staff[Salary]) -> 73861.325 | G3: =MAX(Staff[Salary]) -> 120000
B5: Department | C5: Headcount | D5: Avg. Salary | E5: %diff from overall avg. | G5: Highest Salary | H5: Median salary | I5: Female Ratio
B6: {=_xlfn._xlws.SORT(_xlfn.UNIQUE(Staff[Department]))} -> Accounting | C6: {=COUNTIFS(Staff[Department],_xlfn.ANCHORARRAY(B6))} -> 26 | D6: {=AVERAGEIFS(Staff[Salary],Staff[Department],_xlfn.ANCHORARRAY(B6))} -> 69806.946 | E6: {=_xlfn.ANCHORARRAY(D6)-D3} -> -4054.3795 | F6: {=_xlfn.ANCHORARRAY(E6)} -> -4054.3795 | G6: {=_xlfn.MAXIFS(Staff[Salary],Staff[Department],_xlfn.ANCHORARRAY(B6))} -> 119022.49
B7: Business Development | C7: 26 | D7: 79781.806 | E7: 5920.4805 | F7: 5920.4805 | G7: 110042.37
B8: Engineering | C8: 26 | D8: 81976.442 | E8: 8115.1167 | F8: 8115.1167 | G8: 120000
B9: Human Resources | C9: 22 | D9: 73109.378 | E9: -751.9475 | F9: -751.9475 | G9: 103494.94
B10: Legal | C10: 21 | D10: 67242.518 | E10: -6618.8076 | F10: -6618.8076 | G10: 113747.56
B11: Marketing | C11: 12 | D11: 64441.3 | E11: -9420.0252 | F11: -9420.0252 | G11: 104903.79
B12: Product Management | C12: 29 | D12: 75179.064 | E12: 1317.7393 | F12: 1317.7393 | G12: 115191.38
B13: Research and Development | C13: 18 | D13: 66910.766 | E13: -6950.5597 | F13: -6950.5597 | G13: 99683.67
B14: Sales | C14: 18 | D14: 71897.096 | E14: -1964.2297 | F14: -1964.2297 | G14: 102129.37
B15: Services | C15: 21 | D15: 74673.975 | E15: 812.64953 | F15: 812.64953 | G15: 120000
B16: Support | C16: 17 | D16: 66432.456 | E16: -7428.8693 | F16: -7428.8693 | G16: 104802.63
B17: Training | C17: 24 | D17: 83883.965 | E17: 10022.64 | F17: 10022.64 | G17: 116767.63

Sheet pivot concepts
C1: Pivot Tables in Excel
C5: Analysis Themes: | E5: Concepts introduced:
C6: 1 | D6: How many calls we are getting by customer? | E6: Pivoting data
C7: 2 | D7: How satisfied are our customers? | E7: Chaging calculation mode
C8: 3 | D8: Who are our top 10 customers? | E8: Filters
C9: 4 | D9: Top 10 customers for a specific representative? | E9: Report filters / slicers
C10: 5 | D10: Call duration analysis | E10: Grouping / bucketing
C11: 6 | D11: How busy is our call centre in 2023? | E11: Trends / pivot chart
C12: 7 | D12: YTD Sales Analysis | E12: Value settings
C13: 8 | D13: Which days of week are the busiest? | E13: Conditional formatting
C14: 9 | D14: Is there a link between call duration and satisfaction rating? | E14: Adding columns, refresh, scatter graph
C15: 10 | D15: Should we hire extra people in any specific months? | E15: Conditional formatting
C17: H1 | D17: Time wasters: Which customers call most but buy least?
C18: H2 | D18: Rep training: Which rep(s) could use satisfaction training program?

Sheet Call centre data
B1: Call Centre Data
B3: Call number | C3: Customer ID | D3: Duration | E3: Representative | F3: Date of Call | G3: Purchase Amount | H3: Satisfaction Rating | I3: FY | J3: Day of week | K3: Duration Bucket | L3: Rating Rounded | N3: Customer ID | O3: Gedner | P3: Age | Q3: City
B4: Call_7271 | C4: C0003 | D4: 116 | E4: R05 | F4: 44927 | G4: 128 | H4: 4.9 | I4: =IF(MONTH(Calls[[#This Row],[Date of Call]])<=6, YEAR(Calls[[#This Row],[Date of Call]]),YEAR(Calls[[#This Row],[Date of Call]])+1) -> 2023 | J4: =TEXT(Calls[[#This Row],[Date of Call]],"DDDD") -> Sunday | K4: {=_xlfn.IFS(Calls[[#This Row],[Duration]]<=10,"Under 10 mins",Calls[[#This Row],[Duration]]<=30,"10 to 30 mins", Calls[[#This Row],[Duration]]<60,"30 to 60 mins", Calls[[#This Row],[Duration]]<=120,"1 to 2 hours",TRUE, "More than 2 hours")} -> 1 to 2 hours | L4: =ROUND(Calls[[#This Row],[Satisfaction Rating]],0) -> 5 | N4: C0001 | O4: Male | P4: 41 | Q4: Columbus
B5: Call_7272 | C5: C0004 | D5: 119 | E5: R05 | F5: 44927 | G5: 135 | H5: 2.9 | I5: =IF(MONTH(Calls[[#This Row],[Date of Call]])<=6, YEAR(Calls[[#This Row],[Date of Call]]),YEAR(Calls[[#This Row],[Date of Call]])+1) -> 2023 | J5: =TEXT(Calls[[#This Row],[Date of Call]],"DDDD") -> Sunday | K5: {=_xlfn.IFS(Calls[[#This Row],[Duration]]<=10,"Under 10 mins",Calls[[#This Row],[Duration]]<=30,"10 to 30 mins", Calls[[#This Row],[Duration]]<60,"30 to 60 mins", Calls[[#This Row],[Duration]]<=120,"1 to 2 hours",TRUE, "More than 2 hours")} -> 1 to 2 hours | L5: =ROUND(Calls[[#This Row],[Satisfaction Rating]],0) -> 3 | N5: C0002 | O5: Male | P5: 31 | Q5: Cleveland
B6: Call_7273 | C6: C0005 | D6: 68 | E6: R02 | F6: 44927 | G6: 66 | H6: 4.7 | I6: =IF(MONTH(Calls[[#This Row],[Date of Call]])<=6, YEAR(Calls[[#This Row],[Date of Call]]),YEAR(Calls[[#This Row],[Date of Call]])+1) -> 2023 | J6: =TEXT(Calls[[#This Row],[Date of Call]],"DDDD") -> Sunday | K6: {=_xlfn.IFS(Calls[[#This Row],[Duration]]<=10,"Under 10 mins",Calls[[#This Row],[Duration]]<=30,"10 to 30 mins", Calls[[#This Row],[Duration]]<60,"30 to 60 mins", Calls[[#This Row],[Duration]]<=120,"1 to 2 hours",TRUE, "More than 2 hours")} -> 1 to 2 hours | L6: =ROUND(Calls[[#This Row],[Satisfaction Rating]],0) -> 5 | N6: C0003 | O6: Male | P6: 26 | Q6: Cincinnati
B7: Call_7274 | C7: C0014 | D7: 119 | E7: R02 | F7: 44927 | G7: 22 | H7: 2.9 | I7: =IF(MONTH(Calls[[#This Row],[Date of Call]])<=6, YEAR(Calls[[#This Row],[Date of Call]]),YEAR(Calls[[#This Row],[Date of Call]])+1) -> 2023 | J7: =TEXT(Calls[[#This Row],[Date of Call]],"DDDD") -> Sunday | K7: {=_xlfn.IFS(Calls[[#This Row],[Duration]]<=10,"Under 10 mins",Calls[[#This Row],[Duration]]<=30,"10 to 30 mins", Calls[[#This Row],[Duration]]<60,"30 to 60 mins", Calls[[#This Row],[Duration]]<=120,"1 to 2 hours",TRUE, "More than 2 hours")} -> 1 to 2 hours | L7: =ROUND(Calls[[#This Row],[Satisfaction Rating]],0) -> 3 | N7: C0004 | O7: Male | P7: 36 | Q7: Cincinnati
B8: Call_7275 | C8: C0011 | D8: 128 | E8: R01 | F8: 44928 | G8: 31 | H8: 2.8 | I8: =IF(MONTH(Calls[[#This Row],[Date of Call]])<=6, YEAR(Calls[[#This Row],[Date of Call]]),YEAR(Calls[[#This Row],[Date of Call]])+1) -> 2023 | J8: =TEXT(Calls[[#This Row],[Date of Call]],"DDDD") -> Monday | K8: {=_xlfn.IFS(Calls[[#This Row],[Duration]]<=10,"Under 10 mins",Calls[[#This Row],[Duration]]<=30,"10 to 30 mins", Calls[[#This Row],[Duration]]<60,"30 to 60 mins", Calls[[#This Row],[Duration]]<=120,"1 to 2 hours",TRUE, "More than 2 hours")} -> More than 2 hours | L8: =ROUND(Calls[[#This Row],[Satisfaction Rating]],0) -> 3 | N8: C0005 | O8: Male | P8: 37 | Q8: Columbus
B9: Call_7276 | C9: C0011 | D9: 49 | E9: R02 | F9: 44929 | G9: 135 | H9: 4.8 | I9: =IF(MONTH(Calls[[#This Row],[Date of Call]])<=6, YEAR(Calls[[#This Row],[Date of Call]]),YEAR(Calls[[#This Row],[Date of Call]])+1) -> 2023 | J9: =TEXT(Calls[[#This Row],[Date of Call]],"DDDD") -> Tuesday | K9: {=_xlfn.IFS(Calls[[#This Row],[Duration]]<=10,"Under 10 mins",Calls[[#This Row],[Duration]]<=30,"10 to 30 mins", Calls[[#This Row],[Duration]]<60,"30 to 60 mins", Calls[[#This Row],[Duration]]<=120,"1 to 2 hours",TRUE, "More than 2 hours")} -> 30 to 60 mins | L9: =ROUND(Calls[[#This Row],[Satisfaction Rating]],0) -> 5 | N9: C0006 | O9: Male | P9: 23 | Q9: Columbus
B10: Call_7277 | C10: C0007 | D10: 84 | E10: R05 | F10: 44929 | G10: 60 | H10: 4.7 | I10: =IF(MONTH(Calls[[#This Row],[Date of Call]])<=6, YEAR(Calls[[#This Row],[Date of Call]]),YEAR(Calls[[#This Row],[Date of Call]])+1) -> 2023 | J10: =TEXT(Calls[[#This Row],[Date of Call]],"DDDD") -> Tuesday | K10: {=_xlfn.IFS(Calls[[#This Row],[Duration]]<=10,"Under 10 mins",Calls[[#This Row],[Duration]]<=30,"10 to 30 mins", Calls[[#This Row],[Duration]]<60,"30 to 60 mins", Calls[[#This Row],[Duration]]<=120,"1 to 2 hours",TRUE, "More than 2 hours")} -> 1 to 2 hours | L10: =ROUND(Calls[[#This Row],[Satisfaction Rating]],0) -> 5 | N10: C0007 | O10: Female | P10: 22 | Q10: Cleveland
B11: Call_7278 | C11: C0003 | D11: 103 | E11: R04 | F11: 44929 | G11: 148 | H11: 4.4 | I11: =IF(MONTH(Calls[[#This Row],[Date of Call]])<=6, YEAR(Calls[[#This Row],[Date of Call]]),YEAR(Calls[[#This Row],[Date of Call]])+1) -> 2023 | J11: =TEXT(Calls[[#This Row],[Date of Call]],"DDDD") -> Tuesday | K11: {=_xlfn.IFS(Calls[[#This Row],[Duration]]<=10,"Under 10 mins",Calls[[#This Row],[Duration]]<=30,"10 to 30 mins", Calls[[#This Row],[Duration]]<60,"30 to 60 mins", Calls[[#This Row],[Duration]]<=120,"1 to 2 hours",TRUE, "More than 2 hours")} -> 1 to 2 hours | L11: =ROUND(Calls[[#This Row],[Satisfaction Rating]],0) -> 4 | N11: C0008 | O11: Female | P11: 42 | Q11: Cleveland
B12: Call_7279 | C12: C0005 | D12: 31 | E12: R02 | F12: 44929 | G12: 135 | H12: 3.6 | I12: =IF(MONTH(Calls[[#This Row],[Date of Call]])<=6, YEAR(Calls[[#This Row],[Date of Call]]),YEAR(Calls[[#This Row],[Date of Call]])+1) -> 2023 | J12: =TEXT(Calls[[#This Row],[Date of Call]],"DDDD") -> Tuesday | K12: {=_xlfn.IFS(Calls[[#This Row],[Duration]]<=10,"Under 10 mins",Calls[[#This Row],[Duration]]<=30,"10 to 30 mins", Calls[[#This Row],[Duration]]<60,"30 to 60 mins", Calls[[#This Row],[Duration]]<=120,"1 to 2 hours",TRUE, "More than 2 hours")} -> 30 to 60 mins | L12: =ROUND(Calls[[#This Row],[Satisfaction Rating]],0) -> 4 | N12: C0009 | O12: Female | P12: 25 | Q12: Columbus
B13: Call_7280 | C13: C0010 | D13: 44 | E13: R03 | F13: 44929 | G13: 105 | H13: 2.9 | I13: =IF(MONTH(Calls[[#This Row],[Date of Call]])<=6, YEAR(Calls[[#This Row],[Date of Call]]),YEAR(Calls[[#This Row],[Date of Call]])+1) -> 2023 | J13: =TEXT(Calls[[#This Row],[Date of Call]],"DDDD") -> Tuesday | K13: {=_xlfn.IFS(Calls[[#This Row],[Duration]]<=10,"Under 10 mins",Calls[[#This Row],[Duration]]<=30,"10 to 30 mins", Calls[[#This Row],[Duration]]<60,"30 to 60 mins", Calls[[#This Row],[Duration]]<=120,"1 to 2 hours",TRUE, "More than 2 hours")} -> 30 to 60 mins | L13: =ROUND(Calls[[#This Row],[Satisfaction Rating]],0) -> 3 | N13: C0010 | O13: Female | P13: 30 | Q13: Cleveland
B14: Call_7281 | C14: C0011 | D14: 102 | E14: R02 | F14: 44929 | G14: 69 | H14: 4.9 | I14: =IF(MONTH(Calls[[#This Row],[Date of Call]])<=6, YEAR(Calls[[#This Row],[Date of Call]]),YEAR(Calls[[#This Row],[Date of Call]])+1) -> 2023 | J14: =TEXT(Calls[[#This Row],[Date of Call]],"DDDD") -> Tuesday | K14: {=_xlfn.IFS(Calls[[#This Row],[Duration]]<=10,"Under 10 mins",Calls[[#This Row],[Duration]]<=30,"10 to 30 mins", Calls[[#This Row],[Duration]]<60,"30 to 60 mins", Calls[[#This Row],[Duration]]<=120,"1 to 2 hours",TRUE, "More than 2 hours")} -> 1 to 2 hours | L14: =ROUND(Calls[[#This Row],[Satisfaction Rating]],0) -> 5 | N14: C0011 | O14: Female | P14: 30 | Q14: Cincinnati
B15: Call_7282 | C15: C0013 | D15: 135 | E15: R05 | F15: 44929 | G15: 46 | H15: 3.4 | I15: =IF(MONTH(Calls[[#This Row],[Date of Call]])<=6, YEAR(Calls[[#This Row],[Date of Call]]),YEAR(Calls[[#This Row],[Date of Call]])+1) -> 2023 | J15: =TEXT(Calls[[#This Row],[Date of Call]],"DDDD") -> Tuesday | K15: {=_xlfn.IFS(Calls[[#This Row],[Duration]]<=10,"Under 10 mins",Calls[[#This Row],[Duration]]<=30,"10 to 30 mins", Calls[[#This Row],[Duration]]<60,"30 to 60 mins", Calls[[#This Row],[Duration]]<=120,"1 to 2 hours",TRUE, "More than 2 hours")} -> More than 2 hours | L15: =ROUND(Calls[[#This Row],[Satisfaction Rating]],0) -> 3 | N15: C0012 | O15: Female | P15: 28 | Q15: Cincinnati
... B18: Call_7285 | C18: C0013 | D18: 48 | E18: R01 | F18: 44930 | G18: 68 | H18: 4.9 | I18: =IF(MONTH(Calls[[#This Row],[Date of Call]])<=6, YEAR(Calls[[#This Row],[Date of Call]]),YEAR(Calls[[#This Row],[Date of Call]])+1) -> 2023 | J18: =TEXT(Calls[[#This Row],[Date of Call]],"DDDD") -> Wednesday | K18: {=_xlfn.IFS(Calls[[#This Row],[Duration]]<=10,"Under 10 mins",Calls[[#This Row],[Duration]]<=30,"10 to 30 mins", Calls[[#This Row],[Duration]]<60,"30 to 60 mins", Calls[[#This Row],[Duration]]<=120,"1 to 2 hours",TRUE, "More than 2 hours")} -> 30 to 60 mins | L18: =ROUND(Calls[[#This Row],[Satisfaction Rating]],0) -> 5 | N18: C0015 | O18: Female | P18: 43 | Q18: Cleveland
B19: Call_7286 | C19: C0010 | D19: 176 | E19: R05 | F19: 44931 | G19: 24 | H19: 4.8 | I19: =IF(MONTH(Calls[[#This Row],[Date of Call]])<=6, YEAR(Calls[[#This Row],[Date of Call]]),YEAR(Calls[[#This Row],[Date of Call]])+1) -> 2023 | J19: =TEXT(Calls[[#This Row],[Date of Call]],"DDDD") -> Thursday | K19: {=_xlfn.IFS(Calls[[#This Row],[Duration]]<=10,"Under 10 mins",Calls[[#This Row],[Duration]]<=30,"10 to 30 mins", Calls[[#This Row],[Duration]]<60,"30 to 60 mins", Calls[[#This Row],[Duration]]<=120,"1 to 2 hours",TRUE, "More than 2 hours")} -> More than 2 hours | L19: =ROUND(Calls[[#This Row],[Satisfaction Rating]],0) -> 5
B20: Call_7287 | C20: C0010 | D20: 99 | E20: R01 | F20: 44931 | G20: 195 | H20: 3.9 | I20: =IF(MONTH(Calls[[#This Row],[Date of Call]])<=6, YEAR(Calls[[#This Row],[Date of Call]]),YEAR(Calls[[#This Row],[Date of Call]])+1) -> 2023 | J20: =TEXT(Calls[[#This Row],[Date of Call]],"DDDD") -> Thursday | K20: {=_xlfn.IFS(Calls[[#This Row],[Duration]]<=10,"Under 10 mins",Calls[[#This Row],[Duration]]<=30,"10 to 30 mins", Calls[[#This Row],[Duration]]<60,"30 to 60 mins", Calls[[#This Row],[Duration]]<=120,"1 to 2 hours",TRUE, "More than 2 hours")} -> 1 to 2 hours | L20: =ROUND(Calls[[#This Row],[Satisfaction Rating]],0) -> 4
B21: Call_7288 | C21: C0009 | D21: 28 | E21: R03 | F21: 44931 | G21: 28 | H21: 3.8 | I21: =IF(MONTH(Calls[[#This Row],[Date of Call]])<=6, YEAR(Calls[[#This Row],[Date of Call]]),YEAR(Calls[[#This Row],[Date of Call]])+1) -> 2023 | J21: =TEXT(Calls[[#This Row],[Date of Call]],"DDDD") -> Thursday | K21: {=_xlfn.IFS(Calls[[#This Row],[Duration]]<=10,"Under 10 mins",Calls[[#This Row],[Duration]]<=30,"10 to 30 mins", Calls[[#This Row],[Duration]]<60,"30 to 60 mins", Calls[[#This Row],[Duration]]<=120,"1 to 2 hours",TRUE, "More than 2 hours")} -> 10 to 30 mins | L21: =ROUND(Calls[[#This Row],[Satisfaction Rating]],0) -> 4
B22: Call_7289 | C22: C0007 | D22: 54 | E22: R02 | F22: 44931 | G22: 170 | H22: 4.3 | I22: =IF(MONTH(Calls[[#This Row],[Date of Call]])<=6, YEAR(Calls[[#This Row],[Date of Call]]),YEAR(Calls[[#This Row],[Date of Call]])+1) -> 2023 | J22: =TEXT(Calls[[#This Row],[Date of Call]],"DDDD") -> Thursday | K22: {=_xlfn.IFS(Calls[[#This Row],[Duration]]<=10,"Under 10 mins",Calls[[#This Row],[Duration]]<=30,"10 to 30 mins", Calls[[#This Row],[Duration]]<60,"30 to 60 mins", Calls[[#This Row],[Duration]]<=120,"1 to 2 hours",TRUE, "More than 2 hours")} -> 30 to 60 mins | L22: =ROUND(Calls[[#This Row],[Satisfaction Rating]],0) -> 4
B23: Call_7290 | C23: C0006 | D23: 48 | E23: R05 | F23: 44932 | G23: 30 | H23: 4.4 | I23: =IF(MONTH(Calls[[#This Row],[Date of Call]])<=6, YEAR(Calls[[#This Row],[Date of Call]]),YEAR(Calls[[#This Row],[Date of Call]])+1) -> 2023 | J23: =TEXT(Calls[[#This Row],[Date of Call]],"DDDD") -> Friday | K23: {=_xlfn.IFS(Calls[[#This Row],[Duration]]<=10,"Under 10 mins",Calls[[#This Row],[Duration]]<=30,"10 to 30 mins", Calls[[#This Row],[Duration]]<60,"30 to 60 mins", Calls[[#This Row],[Duration]]<=120,"1 to 2 hours",TRUE, "More than 2 hours")} -> 30 to 60 mins | L23: =ROUND(Calls[[#This Row],[Satisfaction Rating]],0) -> 4
B24: Call_7291 | C24: C0004 | D24: 128 | E24: R05 | F24: 44932 | G24: 72 | H24: 5 | I24: =IF(MONTH(Calls[[#This Row],[Date of Call]])<=6, YEAR(Calls[[#This Row],[Date of Call]]),YEAR(Calls[[#This Row],[Date of Call]])+1) -> 2023 | J24: =TEXT(Calls[[#This Row],[Date of Call]],"DDDD") -> Friday | K24: {=_xlfn.IFS(Calls[[#This Row],[Duration]]<=10,"Under 10 mins",Calls[[#This Row],[Duration]]<=30,"10 to 30 mins", Calls[[#This Row],[Duration]]<60,"30 to 60 mins", Calls[[#This Row],[Duration]]<=120,"1 to 2 hours",TRUE, "More than 2 hours")} -> More than 2 hours | L24: =ROUND(Calls[[#This Row],[Satisfaction Rating]],0) -> 5
B25: Call_7292 | C25: C0004 | D25: 38 | E25: R04 | F25: 44933 | G25: 92 | H25: 4.9 | I25: =IF(MONTH(Calls[[#This Row],[Date of Call]])<=6, YEAR(Calls[[#This Row],[Date of Call]]),YEAR(Calls[[#This Row],[Date of Call]])+1) -> 2023 | J25: =TEXT(Calls[[#This Row],[Date of Call]],"DDDD") -> Saturday | K25: {=_xlfn.IFS(Calls[[#This Row],[Duration]]<=10,"Under 10 mins",Calls[[#This Row],[Duration]]<=30,"10 to 30 mins", Calls[[#This Row],[Duration]]<60,"30 to 60 mins", Calls[[#This Row],[Duration]]<=120,"1 to 2 hours",TRUE, "More than 2 hours")} -> 30 to 60 mins | L25: =ROUND(Calls[[#This Row],[Satisfaction Rating]],0) -> 5
B26: Call_7293 | C26: C0003 | D26: 67 | E26: R04 | F26: 44934 | G26: 165 | H26: 4.5 | I26: =IF(MONTH(Calls[[#This Row],[Date of Call]])<=6, YEAR(Calls[[#This Row],[Date of Call]]),YEAR(Calls[[#This Row],[Date of Call]])+1) -> 2023 | J26: =TEXT(Calls[[#This Row],[Date of Call]],"DDDD") -> Sunday | K26: {=_xlfn.IFS(Calls[[#This Row],[Duration]]<=10,"Under 10 mins",Calls[[#This Row],[Duration]]<=30,"10 to 30 mins", Calls[[#This Row],[Duration]]<60,"30 to 60 mins", Calls[[#This Row],[Duration]]<=120,"1 to 2 hours",TRUE, "More than 2 hours")} -> 1 to 2 hours | L26: =ROUND(Calls[[#This Row],[Satisfaction Rating]],0) -> 5
B27: Call_7294 | C27: C0015 | D27: 58 | E27: R02 | F27: 44934 | G27: 140 | H27: 2.1 | I27: =IF(MONTH(Calls[[#This Row],[Date of Call]])<=6, YEAR(Calls[[#This Row],[Date of Call]]),YEAR(Calls[[#This Row],[Date of Call]])+1) -> 2023 | J27: =TEXT(Calls[[#This Row],[Date of Call]],"DDDD") -> Sunday | K27: {=_xlfn.IFS(Calls[[#This Row],[Duration]]<=10,"Under 10 mins",Calls[[#This Row],[Duration]]<=30,"10 to 30 mins", Calls[[#This Row],[Duration]]<60,"30 to 60 mins", Calls[[#This Row],[Duration]]<=120,"1 to 2 hours",TRUE, "More than 2 hours")} -> 30 to 60 mins | L27: =ROUND(Calls[[#This Row],[Satisfaction Rating]],0) -> 2
B28: Call_7295 | C28: C0010 | D28: 54 | E28: R01 | F28: 44934 | G28: 111 | H28: 3.3 | I28: =IF(MONTH(Calls[[#This Row],[Date of Call]])<=6, YEAR(Calls[[#This Row],[Date of Call]]),YEAR(Calls[[#This Row],[Date of Call]])+1) -> 2023 | J28: =TEXT(Calls[[#This Row],[Date of Call]],"DDDD") -> Sunday | K28: {=_xlfn.IFS(Calls[[#This Row],[Duration]]<=10,"Under 10 mins",Calls[[#This Row],[Duration]]<=30,"10 to 30 mins", Calls[[#This Row],[Duration]]<60,"30 to 60 mins", Calls[[#This Row],[Duration]]<=120,"1 to 2 hours",TRUE, "More than 2 hours")} -> 30 to 60 mins | L28: =ROUND(Calls[[#This Row],[Satisfaction Rating]],0) -> 3
B29: Call_7296 | C29: C0012 | D29: 28 | E29: R05 | F29: 44935 | G29: 63 | H29: 4.1 | I29: =IF(MONTH(Calls[[#This Row],[Date of Call]])<=6, YEAR(Calls[[#This Row],[Date of Call]]),YEAR(Calls[[#This Row],[Date of Call]])+1) -> 2023 | J29: =TEXT(Calls[[#This Row],[Date of Call]],"DDDD") -> Monday | K29: {=_xlfn.IFS(Calls[[#This Row],[Duration]]<=10,"Under 10 mins",Calls[[#This Row],[Duration]]<=30,"10 to 30 mins", Calls[[#This Row],[Duration]]<60,"30 to 60 mins", Calls[[#This Row],[Duration]]<=120,"1 to 2 hours",TRUE, "More than 2 hours")} -> 10 to 30 mins | L29: =ROUND(Calls[[#This Row],[Satisfaction Rating]],0) -> 4
B30: Call_7297 | C30: C0002 | D30: 73 | E30: R05 | F30: 44935 | G30: 80 | H30: 4.2 | I30: =IF(MONTH(Calls[[#This Row],[Date of Call]])<=6, YEAR(Calls[[#This Row],[Date of Call]]),YEAR(Calls[[#This Row],[Date of Call]])+1) -> 2023 | J30: =TEXT(Calls[[#This Row],[Date of Call]],"DDDD") -> Monday | K30: {=_xlfn.IFS(Calls[[#This Row],[Duration]]<=10,"Under 10 mins",Calls[[#This Row],[Duration]]<=30,"10 to 30 mins", Calls[[#This Row],[Duration]]<60,"30 to 60 mins", Calls[[#This Row],[Duration]]<=120,"1 to 2 hours",TRUE, "More than 2 hours")} -> 1 to 2 hours | L30: =ROUND(Calls[[#This Row],[Satisfaction Rating]],0) -> 4
... B1003: Call_8270 | C1003: C0009 | D1003: 114 | E1003: R01 | F1003: 45291 | G1003: 40 | H1003: 3.9 | I1003: =IF(MONTH(Calls[[#This Row],[Date of Call]])<=6, YEAR(Calls[[#This Row],[Date of Call]]),YEAR(Calls[[#This Row],[Date of Call]])+1) -> 2024 | J1003: =TEXT(Calls[[#This Row],[Date of Call]],"DDDD") -> Sunday | K1003: {=_xlfn.IFS(Calls[[#This Row],[Duration]]<=10,"Under 10 mins",Calls[[#This Row],[Duration]]<=30,"10 to 30 mins", Calls[[#This Row],[Duration]]<60,"30 to 60 mins", Calls[[#This Row],[Duration]]<=120,"1 to 2 hours",TRUE, "More than 2 hours")} -> 1 to 2 hours | L1003: =ROUND(Calls[[#This Row],[Satisfaction Rating]],0) -> 4

Sheet Pivot1 & 2
A3: Row Labels | B3: Count of Call number | C3: Average of Satisfaction Rating
A4: C0001 | B4: 65 | C4: 3.8307692
A5: C0002 | B5: 63 | C5: 4.0730159
A6: C0003 | B6: 50 | C6: 4.018
A7: C0004 | B7: 82 | C7: 3.9768293
A8: C0005 | B8: 79 | C8: 3.9797468
A9: C0006 | B9: 62 | C9: 3.7774194
A10: C0007 | B10: 67 | C10: 3.8522388
A11: C0008 | B11: 59 | C11: 3.9016949
A12: C0009 | B12: 69 | C12: 3.626087
A13: C0010 | B13: 72 | C13: 3.8638889
A14: C0011 | B14: 74 | C14: 3.9837838
A15: C0012 | B15: 70 | C15: 4.13
... A19: Grand Total | B19: 1000 | C19: 3.8854

Sheet pivot 3 & 4
A3: Row Labels | B3: Sum of Purchase Amount
A4: C0005 | B4: 7747
A5: C0004 | B5: 7689
A6: C0013 | B6: 7230
A7: C0007 | B7: 7216
A8: C0012 | B8: 6819
A9: C0001 | B9: 6785
A10: C0011 | B10: 6749
A11: C0009 | B11: 6601
A12: C0015 | B12: 6518
A13: C0010 | B13: 6242
A14: Grand Total | B14: 69596

Sheet pivot 5
A3: Row Labels | B3: Count of Call number
A4: Group1 | B4: 9
A5: 2 | B5: 1
A6: 4 | B6: 1
A7: 6 | B7: 3
A8: 7 | B8: 1
A9: 8 | B9: 2
A10: 10 | B10: 1
A11: Group2 | B11: 51
A12: 11 | B12: 1
A13: 12 | B13: 1
A14: 13 | B14: 2
A15: 14 | B15: 1
A16: 15 | B16: 2
A17: 17 | B17: 2
A18: 18 | B18: 4
A19: 19 | B19: 3
A20: 20 | B20: 2
A21: 21 | B21: 4
A22: 23 | B22: 4
A23: 24 | B23: 1
... A29: 30 | B29: 6
A30: Group3 | B30: 179
A31: 31 | B31: 9
A32: 32 | B32: 3
A33: 33 | B33: 3
A34: 34 | B34: 2
A35: 35 | B35: 2
A36: 36 | B36: 4
A37: 37 | B37: 4
A38: 38 | B38: 5
A39: 39 | B39: 4
A40: 40 | B40: 8
A41: 41 | B41: 6
A42: 42 | B42: 3
... A60: 60 | B60: 10
A61: Group4 | B61: 524
A62: 61 | B62: 10
A63: 62 | B63: 8
A64: 63 | B64: 15
...

Sheet pivot 6 & 7
A3: Row Labels | B3: Count of Call number
A4: Jan | B4: 79
A5: Feb | B5: 66
A6: Mar | B6: 155
A7: Apr | B7: 136
A8: May | B8: 83
A9: Jun | B9: 67
A10: Jul | B10: 64
A11: Aug | B11: 50
A12: Sep | B12: 76
A13: Oct | B13: 114
A14: Nov | B14: 57
A15: Dec | B15: 53
A16: Grand Total | B16: 1000
A24: Row Labels | B24: Sum of Purchase Amount
A25: Jan | B25: 7790
A26: Feb | B26: 13912
A27: Mar | B27: 28475
A28: Apr | B28: 42011
A29: May | B29: 50182
A30: Jun | B30: 56075
A31: Jul | B31: 62082
A32: Aug | B32: 67032
A33: Sep | B33: 73721
A34: Oct | B34: 84596
A35: Nov | B35: 91371
A36: Dec | B36: 96623
A37: Grand Total
A44: Row Labels | B44: Sum of Purchase Amount
A45: 2023
A46: Jan | B46: 7790
A47: Feb | B47: 13912
A48: Mar | B48: 28475
A49: Apr | B49: 42011
A50: May | B50: 50182
A51: Jun | B51: 56075
A52: 2024
A53: Jul | B53: 6007
A54: Aug | B54: 10957
A55: Sep | B55: 17646
...

Sheet pivot 8
A3: Count of Call number | B3: Column Labels
A4: Row Labels | B4: Sunday | C4: Monday | D4: Tuesday | E4: Wednesday | F4: Thursday | G4: Friday | H4: Saturday | I4: Grand Total
A5: R01 | B5: 0.19047619 | C5: 0.15873016 | D5: 0.068783069 | E5: 0.12169312 | F5: 0.12169312 | G5: 0.12698413 | H5: 0.21164021 | I5: 1
A6: R02 | B6: 0.12844037 | C6: 0.11009174 | D6: 0.20183486 | E6: 0.16513761 | F6: 0.15137615 | G6: 0.13302752 | H6: 0.11009174 | I6: 1
A7: R03 | B7: 0.14492754 | C7: 0.16425121 | D7: 0.12560386 | E7: 0.18357488 | F7: 0.13043478 | G7: 0.13043478 | H7: 0.12077295 | I7: 1
A8: R04 | B8: 0.1344086 | C8: 0.12365591 | D8: 0.15053763 | E8: 0.15591398 | F8: 0.096774194 | G8: 0.15591398 | H8: 0.1827957 | I8: 1
A9: R05 | B9: 0.135 | C9: 0.11 | D9: 0.135 | E9: 0.135 | F9: 0.135 | G9: 0.16 | H9: 0.19 | I9: 1
A10: Grand Total | B10: 0.146 | C10: 0.133 | D10: 0.138 | E10: 0.153 | F10: 0.128 | G10: 0.141 | H10: 0.161 | I10: 1

Sheet pivot 9
A3: Count of Call number | B3: Column Labels
A4: Row Labels | B4: 5 | C4: 4 | D4: 3 | E4: 2 | F4: 1 | G4: 0 | H4: Grand Total
A5: Under 10 mins | B5: 0.22222222 | C5: 0.55555556 | D5: 0.22222222 | E5: 0 | F5: 0 | G5: 0 | H5: 1
A6: 10 to 30 mins | B6: 0.29411765 | C6: 0.50980392 | D6: 0.11764706 | E6: 0.078431373 | F6: 0 | G6: 0 | H6: 1
A7: 30 to 60 mins | B7: 0.31952663 | C7: 0.41420118 | D7: 0.19526627 | E7: 0.071005917 | F7: 0 | G7: 0 | H7: 1
A8: 1 to 2 hours | B8: 0.30337079 | C8: 0.43071161 | D8: 0.20224719 | E8: 0.054307116 | F8: 0.0093632959 | G8: 0 | H8: 1
A9: More than 2 hours | B9: 0.31223629 | C9: 0.4092827 | D9: 0.20253165 | E9: 0.05907173 | F9: 0.012658228 | G9: 0.0042194093 | H9: 1
A10: Grand Total | B10: 0.307 | C10: 0.428 | D10: 0.197 | E10: 0.059 | F10: 0.008 | G10: 0.001 | H10: 1

Sheet pivot10
A3: Count of Call number | B3: Column Labels
A4: Row Labels | B4: Jan | C4: Feb | D4: Mar | E4: Apr | F4: May | G4: Jun | H4: Jul | I4: Aug | J4: Sep | K4: Oct | L4: Nov | M4: Dec | N4: Grand Total
A5: R01 | B5: 16 | C5: 14 | D5: 26 | E5: 29 | F5: 17 | G5: 15 | H5: 15 | I5: 7 | J5: 11 | K5: 24 | L5: 9 | M5: 6 | N5: 189
A6: R02 | B6: 19 | C6: 10 | D6: 40 | E6: 40 | F6: 13 | G6: 12 | H6: 9 | I6: 13 | J6: 18 | K6: 21 | L6: 14 | M6: 9 | N6: 218
A7: R03 | B7: 13 | C7: 13 | D7: 28 | E7: 24 | F7: 23 | G7: 17 | H7: 11 | I7: 11 | J7: 14 | K7: 30 | L7: 14 | M7: 9 | N7: 207
A8: R04 | B8: 10 | C8: 11 | D8: 30 | E8: 23 | F8: 22 | G8: 11 | H8: 17 | I8: 12 | J8: 13 | K8: 15 | L8: 8 | M8: 14 | N8: 186
A9: R05 | B9: 21 | C9: 18 | D9: 31 | E9: 20 | F9: 8 | G9: 12 | H9: 12 | I9: 7 | J9: 20 | K9: 24 | L9: 12 | M9: 15 | N9: 200
A10: Grand Total | B10: 79 | C10: 66 | D10: 155 | E10: 136 | F10: 83 | G10: 67 | H10: 64 | I10: 50 | J10: 76 | K10: 114 | L10: 57 | M10: 53 | N10: 1000

Sheet calls & cust
B1: Call Centre Data
B3: Call number | C3: Customer ID | D3: Duration | E3: Representative | F3: Date of Call | G3: Purchase Amount | H3: Satisfaction Rating | I3: FY | J3: Day of week | K3: Duration Bucket | L3: Rating Rounded | N3: Customer ID | O3: Gedner | P3: Age | Q3: City
B4: Call_7271 | C4: C0003 | D4: 116 | E4: R05 | F4: 44927 | G4: 128 | H4: 4.9 | I4: =IF(MONTH(CallsTable[[#This Row],[Date of Call]])<=6, YEAR(CallsTable[[#This Row],[Date of Call]]),YEAR(CallsTable[[#This Row],[Date of Call]])+1) -> 2023 | J4: =TEXT(CallsTable[[#This Row],[Date of Call]],"DDDD") -> Sunday | K4: {=_xlfn.IFS(CallsTable[[#This Row],[Duration]]<=10,"Under 10 mins",CallsTable[[#This Row],[Duration]]<=30,"10 to 30 mins", CallsTable[[#This Row],[Duration]]<60,"30 to 60 mins", CallsTable[[#This Row],[Duration]]<=120,"1 to 2 hours",TRUE, "More than 2 hours")} -> 1 to 2 hours | L4: =ROUND(CallsTable[[#This Row],[Satisfaction Rating]],0) -> 5 | N4: C0001 | O4: Male | P4: 41 | Q4: Columbus
B5: Call_7272 | C5: C0004 | D5: 119 | E5: R05 | F5: 44927 | G5: 135 | H5: 2.9 | I5: =IF(MONTH(CallsTable[[#This Row],[Date of Call]])<=6, YEAR(CallsTable[[#This Row],[Date of Call]]),YEAR(CallsTable[[#This Row],[Date of Call]])+1) -> 2023 | J5: =TEXT(CallsTable[[#This Row],[Date of Call]],"DDDD") -> Sunday | K5: {=_xlfn.IFS(CallsTable[[#This Row],[Duration]]<=10,"Under 10 mins",CallsTable[[#This Row],[Duration]]<=30,"10 to 30 mins", CallsTable[[#This Row],[Duration]]<60,"30 to 60 mins", CallsTable[[#This Row],[Duration]]<=120,"1 to 2 hours",TRUE, "More than 2 hours")} -> 1 to 2 hours | L5: =ROUND(CallsTable[[#This Row],[Satisfaction Rating]],0) -> 3 | N5: C0002 | O5: Male | P5: 31 | Q5: Cleveland
B6: Call_7273 | C6: C0005 | D6: 68 | E6: R02 | F6: 44927 | G6: 66 | H6: 4.7 | I6: =IF(MONTH(CallsTable[[#This Row],[Date of Call]])<=6, YEAR(CallsTable[[#This Row],[Date of Call]]),YEAR(CallsTable[[#This Row],[Date of Call]])+1) -> 2023 | J6: =TEXT(CallsTable[[#This Row],[Date of Call]],"DDDD") -> Sunday | K6: {=_xlfn.IFS(CallsTable[[#This Row],[Duration]]<=10,"Under 10 mins",CallsTable[[#This Row],[Duration]]<=30,"10 to 30 mins", CallsTable[[#This Row],[Duration]]<60,"30 to 60 mins", CallsTable[[#This Row],[Duration]]<=120,"1 to 2 hours",TRUE, "More than 2 hours")} -> 1 to 2 hours | L6: =ROUND(CallsTable[[#This Row],[Satisfaction Rating]],0) -> 5 | N6: C0003 | O6: Male | P6: 26 | Q6: Cincinnati
B7: Call_7274 | C7: C0014 | D7: 119 | E7: R02 | F7: 44927 | G7: 22 | H7: 2.9 | I7: =IF(MONTH(CallsTable[[#This Row],[Date of Call]])<=6, YEAR(CallsTable[[#This Row],[Date of Call]]),YEAR(CallsTable[[#This Row],[Date of Call]])+1) -> 2023 | J7: =TEXT(CallsTable[[#This Row],[Date of Call]],"DDDD") -> Sunday | K7: {=_xlfn.IFS(CallsTable[[#This Row],[Duration]]<=10,"Under 10 mins",CallsTable[[#This Row],[Duration]]<=30,"10 to 30 mins", CallsTable[[#This Row],[Duration]]<60,"30 to 60 mins", CallsTable[[#This Row],[Duration]]<=120,"1 to 2 hours",TRUE, "More than 2 hours")} -> 1 to 2 hours | L7: =ROUND(CallsTable[[#This Row],[Satisfaction Rating]],0) -> 3 | N7: C0004 | O7: Male | P7: 36 | Q7: Cincinnati
B8: Call_7275 | C8: C0011 | D8: 128 | E8: R01 | F8: 44928 | G8: 31 | H8: 2.8 | I8: =IF(MONTH(CallsTable[[#This Row],[Date of Call]])<=6, YEAR(CallsTable[[#This Row],[Date of Call]]),YEAR(CallsTable[[#This Row],[Date of Call]])+1) -> 2023 | J8: =TEXT(CallsTable[[#This Row],[Date of Call]],"DDDD") -> Monday | K8: {=_xlfn.IFS(CallsTable[[#This Row],[Duration]]<=10,"Under 10 mins",CallsTable[[#This Row],[Duration]]<=30,"10 to 30 mins", CallsTable[[#This Row],[Duration]]<60,"30 to 60 mins", CallsTable[[#This Row],[Duration]]<=120,"1 to 2 hours",TRUE, "More than 2 hours")} -> More than 2 hours | L8: =ROUND(CallsTable[[#This Row],[Satisfaction Rating]],0) -> 3 | N8: C0005 | O8: Male | P8: 37 | Q8: Columbus
B9: Call_7276 | C9: C0011 | D9: 49 | E9: R02 | F9: 44929 | G9: 135 | H9: 4.8 | I9: =IF(MONTH(CallsTable[[#This Row],[Date of Call]])<=6, YEAR(CallsTable[[#This Row],[Date of Call]]),YEAR(CallsTable[[#This Row],[Date of Call]])+1) -> 2023 | J9: =TEXT(CallsTable[[#This Row],[Date of Call]],"DDDD") -> Tuesday | K9: {=_xlfn.IFS(CallsTable[[#This Row],[Duration]]<=10,"Under 10 mins",CallsTable[[#This Row],[Duration]]<=30,"10 to 30 mins", CallsTable[[#This Row],[Duration]]<60,"30 to 60 mins", CallsTable[[#This Row],[Duration]]<=120,"1 to 2 hours",TRUE, "More than 2 hours")} -> 30 to 60 mins | L9: =ROUND(CallsTable[[#This Row],[Satisfaction Rating]],0) -> 5 | N9: C0006 | O9: Male | P9: 23 | Q9: Columbus
B10: Call_7277 | C10: C0007 | D10: 84 | E10: R05 | F10: 44929 | G10: 60 | H10: 4.7 | I10: =IF(MONTH(CallsTable[[#This Row],[Date of Call]])<=6, YEAR(CallsTable[[#This Row],[Date of Call]]),YEAR(CallsTable[[#This Row],[Date of Call]])+1) -> 2023 | J10: =TEXT(CallsTable[[#This Row],[Date of Call]],"DDDD") -> Tuesday | K10: {=_xlfn.IFS(CallsTable[[#This Row],[Duration]]<=10,"Under 10 mins",CallsTable[[#This Row],[Duration]]<=30,"10 to 30 mins", CallsTable[[#This Row],[Duration]]<60,"30 to 60 mins", CallsTable[[#This Row],[Duration]]<=120,"1 to 2 hours",TRUE, "More than 2 hours")} -> 1 to 2 hours | L10: =ROUND(CallsTable[[#This Row],[Satisfaction Rating]],0) -> 5 | N10: C0007 | O10: Female | P10: 22 | Q10: Cleveland
B11: Call_7278 | C11: C0003 | D11: 103 | E11: R04 | F11: 44929 | G11: 148 | H11: 4.4 | I11: =IF(MONTH(CallsTable[[#This Row],[Date of Call]])<=6, YEAR(CallsTable[[#This Row],[Date of Call]]),YEAR(CallsTable[[#This Row],[Date of Call]])+1) -> 2023 | J11: =TEXT(CallsTable[[#This Row],[Date of Call]],"DDDD") -> Tuesday | K11: {=_xlfn.IFS(CallsTable[[#This Row],[Duration]]<=10,"Under 10 mins",CallsTable[[#This Row],[Duration]]<=30,"10 to 30 mins", CallsTable[[#This Row],[Duration]]<60,"30 to 60 mins", CallsTable[[#This Row],[Duration]]<=120,"1 to 2 hours",TRUE, "More than 2 hours")} -> 1 to 2 hours | L11: =ROUND(CallsTable[[#This Row],[Satisfaction Rating]],0) -> 4 | N11: C0008 | O11: Female | P11: 42 | Q11: Cleveland
B12: Call_7279 | C12: C0005 | D12: 31 | E12: R02 | F12: 44929 | G12: 135 | H12: 3.6 | I12: =IF(MONTH(CallsTable[[#This Row],[Date of Call]])<=6, YEAR(CallsTable[[#This Row],[Date of Call]]),YEAR(CallsTable[[#This Row],[Date of Call]])+1) -> 2023 | J12: =TEXT(CallsTable[[#This Row],[Date of Call]],"DDDD") -> Tuesday | K12: {=_xlfn.IFS(CallsTable[[#This Row],[Duration]]<=10,"Under 10 mins",CallsTable[[#This Row],[Duration]]<=30,"10 to 30 mins", CallsTable[[#This Row],[Duration]]<60,"30 to 60 mins", CallsTable[[#This Row],[Duration]]<=120,"1 to 2 hours",TRUE, "More than 2 hours")} -> 30 to 60 mins | L12: =ROUND(CallsTable[[#This Row],[Satisfaction Rating]],0) -> 4 | N12: C0009 | O12: Female | P12: 25 | Q12: Columbus
B13: Call_7280 | C13: C0010 | D13: 44 | E13: R03 | F13: 44929 | G13: 105 | H13: 2.9 | I13: =IF(MONTH(CallsTable[[#This Row],[Date of Call]])<=6, YEAR(CallsTable[[#This Row],[Date of Call]]),YEAR(CallsTable[[#This Row],[Date of Call]])+1) -> 2023 | J13: =TEXT(CallsTable[[#This Row],[Date of Call]],"DDDD") -> Tuesday | K13: {=_xlfn.IFS(CallsTable[[#This Row],[Duration]]<=10,"Under 10 mins",CallsTable[[#This Row],[Duration]]<=30,"10 to 30 mins", CallsTable[[#This Row],[Duration]]<60,"30 to 60 mins", CallsTable[[#This Row],[Duration]]<=120,"1 to 2 hours",TRUE, "More than 2 hours")} -> 30 to 60 mins | L13: =ROUND(CallsTable[[#This Row],[Satisfaction Rating]],0) -> 3 | N13: C0010 | O13: Female | P13: 30 | Q13: Cleveland
B14: Call_7281 | C14: C0011 | D14: 102 | E14: R02 | F14: 44929 | G14: 69 | H14: 4.9 | I14: =IF(MONTH(CallsTable[[#This Row],[Date of Call]])<=6, YEAR(CallsTable[[#This Row],[Date of Call]]),YEAR(CallsTable[[#This Row],[Date of Call]])+1) -> 2023 | J14: =TEXT(CallsTable[[#This Row],[Date of Call]],"DDDD") -> Tuesday | K14: {=_xlfn.IFS(CallsTable[[#This Row],[Duration]]<=10,"Under 10 mins",CallsTable[[#This Row],[Duration]]<=30,"10 to 30 mins", CallsTable[[#This Row],[Duration]]<60,"30 to 60 mins", CallsTable[[#This Row],[Duration]]<=120,"1 to 2 hours",TRUE, "More than 2 hours")} -> 1 to 2 hours | L14: =ROUND(CallsTable[[#This Row],[Satisfaction Rating]],0) -> 5 | N14: C0011 | O14: Female | P14: 30 | Q14: Cincinnati
